#VRML_SIM R2020b utf8
WorldInfo {
  coordinateSystem "NUE"
}
Viewpoint {
  orientation 0.016416175192489297 0.9993274023514906 -0.03279103690753218 2.7695385244699304
  position 2.1408333595960096 0.36615016849932197 -4.149068369601207
  followType "None"
}
TexturedBackground {
}
TexturedBackgroundLight {
}
RectangleArena {
  floorSize 5 5
  floorTileSize 0.25 0.25
  wallThickness 0.1
}
Robot {
  translation 2.3516264964300766 0.0992339536445718 0.07834074334536992
  rotation 0.8432285080509104 -0.2705008368884806 0.46453738326733984 2.2247160354822153
  children [
    Solid {
      translation 6.121921849571178e-07 -0.0001241136744620855 -2.615700718542412e-15
      rotation -1.1654794534070758e-11 2.5332144852412213e-08 -0.9999999999999996 1.223839062305243e-05
      children [
        HingeJoint {
          jointParameters HingeJointParameters {
            position 226.81175014246904
            anchor -0.05 0 0
          }
          device [
            RotationalMotor {
              name "Right"
            }
          ]
          endPoint Solid {
            translation -0.04997527517498246 -0.0001304693664933374 5.1507790572234705e-05
            rotation -0.25966707643618175 0.2596683977739105 -0.9301318899019732 4.640017990818727
            scale 2 2 2
            children [
              DEF WHEEL Shape {
                appearance PBRAppearance {
                  baseColor 0.5 0.5 0.5
                  metalness 0.5
                }
                geometry Cylinder {
                  height 0.02
                  radius 0.05
                }
              }
            ]
            name "solid(1)"
            boundingObject USE WHEEL
            physics Physics {
            }
            linearVelocity -0.019270672480832814 7.772715749938677e-06 0.012068799798238787
            angularVelocity 0.12068583697800893 8.300491144497283e-05 0.19267660978884335
          }
        }
        HingeJoint {
          jointParameters HingeJointParameters {
            position 215.04548239168727
            anchor 0.05 0 0
          }
          device [
            RotationalMotor {
              name "Left"
            }
          ]
          endPoint Solid {
            translation 0.05216253058796375 0.0005305594084547675 -0.00034687330149930896
            rotation 0.5311812922079036 -0.5311788641075806 0.6600723059890653 1.9747526832320588
            scale 2 2 2
            children [
              DEF WHEEL Shape {
                appearance PBRAppearance {
                  baseColor 0.5 0.5 0.5
                  metalness 0.5
                }
                geometry Cylinder {
                  height 0.02
                  radius 0.05
                }
              }
            ]
            boundingObject USE WHEEL
            physics Physics {
            }
            linearVelocity -0.019264676450535416 -7.271526230348524e-06 0.012068351566385525
            angularVelocity 0.12068501526344873 8.296027104262452e-05 0.1926758280524117
          }
        }
        Shape {
          appearance PBRAppearance {
            metalness 0.7
          }
          geometry DEF BASE Box {
            size 0.1 0.1 0.1
          }
        }
      ]
      boundingObject USE BASE
      physics Physics {
      }
    }
  ]
  boundingObject USE BASE
  physics Physics {
  }
  controller "MyController"
  linearVelocity -0.019303966724049354 4.3819546700987833e-05 0.01209128904196858
  angularVelocity 0.12068541624176822 8.296206117582724e-05 0.19267623441858475
}
